<?xml version="1.0" ?>
<robot name="Biped_12DOF_torsoappended_190923">

<material name="silver">
  <color rgba="0.700 0.700 0.700 1.000"/>
</material>

<link name="base_box">
  <inertial>
    
    <!--origin xyz="-0.07139043603557767 -0.16954551899156534 0.300032870177832" rpy="0 0 0"/-->
    <mass value="0.01"/>
    <inertia ixx="0.00025" ixy="0" ixz="0" iyy="0.00089" iyz="0" izz="0.00064"/>
     
     <!--inertia ixx="0.00250000000000000006" ixy="0" ixz="0" iyy="0.0089000000000000002" iyz="0" izz="0.00640" for m= 1/-->
  </inertial>
  <visual>
    <origin xyz="0 0 0" rpy="0 0 0"/>
    <geometry>
      <!--box size=".08 .02 .05"/-->
      <box size="0 0 0"/>
    </geometry>
    <material name="silver"/>
    <material/>
  </visual>
  <collision>
    <origin xyz="0 0 0" rpy="0 0 0"/>
    <geometry>
      <box size="0.0 0.0 0.0"/>
    </geometry>
  </collision>
</link>


<link name="base_link">
  <inertial>
    <origin xyz="0.06060872462491695 0.036723589973975845 0.30999861161402337" rpy="0 0 0"/>
    <mass value="0.02188916916153513"/>
    <inertia ixx="1.4745375687328505e-05" iyy="2.054443019497247e-05" izz="3.527521310286041e-05" ixy="-9.684751620381694e-09" iyz="-2.168404344971009e-19" ixz="1.0842021724855044e-19"/>
  </inertial>
  <visual>
    <origin xyz="0 0 0" rpy="0 0 0"/>
    <geometry>
      <mesh filename="meshes/base_link.stl" scale="0.001 0.001 0.001"/>
    </geometry>
    <material name="silver"/>
    <material/>
  </visual>
  <collision>
    <origin xyz="0 0 0" rpy="0 0 0"/>
    <geometry>
      <mesh filename="meshes/base_link.stl" scale="0.001 0.001 0.001"/>
    </geometry>
  </collision>
</link>

<link name="connect_link_v11">
  <inertial>
    <origin xyz="8.755939062687901e-08 -0.005999506282332957 -0.0032503883859776317" rpy="0 0 0"/>
    <mass value="0.00969209120805048"/>
    <inertia ixx="4.4427801889897027e-07" iyy="2.5957966162830142e-06" izz="2.9718261595912686e-06" ixy="5.759824041329242e-20" iyz="-2.710505431213761e-20" ixz="0.0"/>
  </inertial>
  <visual>
    <origin xyz="-0.060628 -0.038873 -0.308999" rpy="0 0 0"/>
    <geometry>
      <mesh filename="meshes/connect_link_v11.stl" scale="0.001 0.001 0.001"/>
    </geometry>
    <material name="silver"/>
    <material/>
  </visual>
  <collision>
    <origin xyz="-0.060628 -0.038873 -0.308999" rpy="0 0 0"/>
    <geometry>
      <mesh filename="meshes/connect_link_v11.stl" scale="0.001 0.001 0.001"/>
    </geometry>
  </collision>
</link>

<link name="Hip_servo_Yaw_L1">
  <inertial>
    <origin xyz="-0.013531113018413154 -0.00969047444291548 -0.01700249284622163" rpy="0 0 0"/>
    <mass value="0.0811"/>
    <inertia ixx="2.3417335463269515e-05" iyy="12.961400395210524e-06" izz="1.969636612402693e-05" ixy="2.0523614970348356e-08" iyz="-1.5930335249283921e-07" ixz="-2.7805076826824883e-09"/>
  </inertial>
  <visual>
    <origin xyz="-0.035628 -0.032873 -0.302499" rpy="0 0 0"/>
    <geometry>
      <mesh filename="meshes/Hip_servo_Yaw_L1.stl" scale="0.001 0.001 0.001"/>
    </geometry>
    <material name="silver"/>
    <material/>
  </visual>
  <collision>
    <origin xyz="-0.035628 -0.032873 -0.302499" rpy="0 0 0"/>
    <geometry>
      <mesh filename="meshes/Hip_servo_Yaw_L1.stl" scale="0.001 0.001 0.001"/>
    </geometry>
  </collision>
</link>

<link name="Hip_servo_Yaw__R_1">
  <inertial>
    <origin xyz="0.013468886981585007 -0.00969047444291786 -0.016802492846221484" rpy="0 0 0"/>
    <mass value="0.0811"/>
    <inertia ixx="2.3417335463269515e-05" iyy="12.961400395210524e-06" izz="1.969636612402693e-05" ixy="2.0523614970348356e-08" iyz="-1.5930335249283921e-07" ixz="-2.7805076826824883e-09"/>
  </inertial>
  <visual>
    <origin xyz="-0.085628 -0.032873 -0.302499" rpy="0 0 0"/>
    <geometry>
      <mesh filename="meshes/Hip_servo_Yaw__R_1.stl" scale="0.001 0.001 0.001"/>
    </geometry>
    <material name="silver"/>
    <material/>
  </visual>
  <collision>
    <origin xyz="-0.085628 -0.032873 -0.302499" rpy="0 0 0"/>
    <geometry>
      <mesh filename="meshes/Hip_servo_Yaw__R_1.stl" scale="0.001 0.001 0.001"/>
    </geometry>
  </collision>
</link>

<link name="connect_link_21">
  <inertial>
    <origin xyz="0.025000087559390392 4.93717667540694e-07 -0.0007503883859772409" rpy="0 0 0"/>
    <mass value="0.0022366364326270346"/>
    <inertia ixx="9.507024189355125e-08" iyy="5.915745335974634e-07" izz="6.858060368287546e-07" ixy="1.4399560103323106e-20" iyz="3.3881317890172014e-21" ixz="6.776263578034403e-21"/>
  </inertial>
  <visual>
    <origin xyz="-0.035628 -0.032873 -0.270499" rpy="0 0 0"/>
    <geometry>
      <mesh filename="meshes/connect_link_21.stl" scale="0.001 0.001 0.001"/>
    </geometry>
    <material name="silver"/>
    <material/>
  </visual>
  <collision>
    <origin xyz="-0.035628 -0.032873 -0.270499" rpy="0 0 0"/>
    <geometry>
      <mesh filename="meshes/connect_link_21.stl" scale="0.001 0.001 0.001"/>
    </geometry>
  </collision>
</link>

<link name="support_link1">
  <inertial>
    <origin xyz="8.755938650517603e-08 -0.01899092222380293 0.008312349694208576" rpy="0 0 0"/>
    <mass value="0.004271598629814522"/>
    <inertia ixx="9.380132827919367e-07" iyy="9.819874908971005e-07" izz="8.644459883259723e-07" ixy="-2.82061971435682e-19" iyz="2.809956492261554e-07" ixz="1.4907779871675686e-19"/>
  </inertial>
  <visual>
    <origin xyz="-0.060628 -0.038873 -0.268999" rpy="0 0 0"/>
    <geometry>
      <mesh filename="meshes/support_link1.stl" scale="0.001 0.001 0.001"/>
    </geometry>
    <material name="silver"/>
    <material/>
  </visual>
  <collision>
    <origin xyz="-0.060628 -0.038873 -0.268999" rpy="0 0 0"/>
    <geometry>
      <mesh filename="meshes/support_link1.stl" scale="0.001 0.001 0.001"/>
    </geometry>
  </collision>
</link>

<link name="Hip_bracket_yaw_L_v11">
  <inertial>
    <origin xyz="8.755937528151514e-08 -0.00019455926519733498 -0.012368152810058874" rpy="0 0 0"/>
    <mass value="0.008735700587823858"/>
    <inertia ixx="4.557715173367227e-06" iyy="1.596604357873184e-06" izz="3.6811077103368883e-06" ixy="-8.343274530454858e-20" iyz="-2.8340072973809954e-08" ixz="-3.503328269843786e-18"/>
  </inertial>
  <visual>
    <origin xyz="-0.022128 -0.010373 -0.265499" rpy="0 0 0"/>
    <geometry>
      <mesh filename="meshes/Hip_bracket_yaw_L_v11.stl" scale="0.001 0.001 0.001"/>
    </geometry>
    <material name="silver"/>
    <material/>
  </visual>
  <collision>
    <origin xyz="-0.022128 -0.010373 -0.265499" rpy="0 0 0"/>
    <geometry>
      <mesh filename="meshes/Hip_bracket_yaw_L_v11.stl" scale="0.001 0.001 0.001"/>
    </geometry>
  </collision>
</link>

<link name="Hip_Bracket_yaw_R1">
  <inertial>
    <origin xyz="8.755937279392167e-08 -0.0001945592651994444 -0.012368152810057986" rpy="0 0 0"/>
    <mass value="0.008735700587823858"/>
    <inertia ixx="4.557715173370263e-06" iyy="1.5966043578800144e-06" izz="3.681107710333268e-06" ixy="-7.115076756936123e-20" iyz="-2.8340072973769297e-08" ixz="-3.415236843329339e-18"/>
  </inertial>
  <visual>
    <origin xyz="-0.099128 -0.010373 -0.265699" rpy="0 0 0"/>
    <geometry>
      <mesh filename="meshes/Hip_Bracket_yaw_R1.stl" scale="0.001 0.001 0.001"/>
    </geometry>
    <material name="silver"/>
    <material/>
  </visual>
  <collision>
    <origin xyz="-0.099128 -0.010373 -0.265699" rpy="0 0 0"/>
    <geometry>
      <mesh filename="meshes/Hip_Bracket_yaw_R1.stl" scale="0.001 0.001 0.001"/>
    </geometry>
  </collision>
</link>

<link name="Bush_2_1">
  <inertial>
    <origin xyz="0.022128087559382902 0.21457600178506725 -0.04262638838534463" rpy="0 0 0"/>
    <mass value="0.00033912761870964644"/>
    <inertia ixx="3.5534106983028924e-09" iyy="4.084788845227892e-09" izz="3.553410474846204e-09" ixy="-2.6469779601696886e-23" iyz="-1.4336032632279033e-19" ixz="2.117582368135751e-22"/>
  </inertial>
  <visual>
    <origin xyz="0.0 0.226125 -0.279125" rpy="0 0 0"/>
    <geometry>
      <mesh filename="meshes/Bush_2_1.stl" scale="0.001 0.001 0.001"/>
    </geometry>
    <material name="silver"/>
    <material/>
  </visual>
  <collision>
    <origin xyz="0.0 0.226125 -0.279125" rpy="0 0 0"/>
    <geometry>
      <mesh filename="meshes/Bush_2_1.stl" scale="0.001 0.001 0.001"/>
    </geometry>
  </collision>
</link>

<link name="Bush_1_v11">
  <inertial>
    <origin xyz="-0.07712791244061934 -0.2586209982149346 -0.04262638838534433" rpy="0 0 0"/>
    <mass value="0.00033912761870964644"/>
    <inertia ixx="3.5534106983028924e-09" iyy="4.084788845234668e-09" izz="3.553410474846707e-09" ixy="5.293955920339377e-23" iyz="-1.4336032632279033e-19" ixz="0.0"/>
  </inertial>
  <visual>
    <origin xyz="-0.176256 -0.247072 -0.279325" rpy="0 0 0"/>
    <geometry>
      <mesh filename="meshes/Bush_1_v11.stl" scale="0.001 0.001 0.001"/>
    </geometry>
    <material name="silver"/>
    <material/>
  </visual>
  <collision>
    <origin xyz="-0.176256 -0.247072 -0.279325" rpy="0 0 0"/>
    <geometry>
      <mesh filename="meshes/Bush_1_v11.stl" scale="0.001 0.001 0.001"/>
    </geometry>
  </collision>
</link>

<link name="Washer_11">
  <inertial>
    <origin xyz="-0.09912791244096347 -0.008551506282331372 0.2366986116140234" rpy="0 0 0"/>
    <mass value="0.0001569470040624276"/>
    <inertia ixx="2.095397917133054e-09" iyy="4.096365919137407e-09" izz="2.095397782786852e-09" ixy="2.6469779601696886e-23" iyz="0.0" ixz="4.235164736271502e-22"/>
  </inertial>
  <visual>
    <origin xyz="-0.198256 -0.0 -0.0" rpy="0 0 0"/>
    <geometry>
      <mesh filename="meshes/Washer_11.stl" scale="0.001 0.001 0.001"/>
    </geometry>
    <material name="silver"/>
    <material/>
  </visual>
  <collision>
    <origin xyz="-0.198256 -0.0 -0.0" rpy="0 0 0"/>
    <geometry>
      <mesh filename="meshes/Washer_11.stl" scale="0.001 0.001 0.001"/>
    </geometry>
  </collision>
</link>

<link name="Hip_servo_roll_L1">
  <inertial>
    <origin xyz="0.02212792246244539 0.28094966903192353 -0.005937424755607296" rpy="0 0 0"/>
     <mass value="0.0811"/>
    <inertia ixx="2.3417335463269515e-05" iyy="12.961400395210524e-06" izz="1.969636612402693e-05" ixy="2.0523614970348356e-08" iyz="-1.5930335249283921e-07" ixz="-2.7805076826824883e-09"/>
  </inertial>
  <visual>
    <origin xyz="0.0 0.226125 -0.231125" rpy="0 0 0"/>
    <geometry>
      <mesh filename="meshes/Hip_servo_roll_L1.stl" scale="0.001 0.001 0.001"/>
    </geometry>
    <material name="silver"/>
    <material/>
  </visual>
  <collision>
    <origin xyz="0.0 0.226125 -0.231125" rpy="0 0 0"/>
    <geometry>
      <mesh filename="meshes/Hip_servo_roll_L1.stl" scale="0.001 0.001 0.001"/>
    </geometry>
  </collision>
</link>

<link name="Support_roll_servo_L1">
  <inertial>
    <origin xyz="-0.008342818068121632 -0.007693332734379908 -8.605220785384837e-07" rpy="0 0 0"/>
    <mass value="0.001003390579055556"/>
    <inertia ixx="5.969253484000835e-08" iyy="1.9068402818395841e-07" izz="2.44845355143008e-07" ixy="-1.0691242380712038e-09" iyz="-8.557850778121313e-13" ixz="1.6064752087411026e-10"/>
  </inertial>
  <visual>
    <origin xyz="-0.030628 -0.040148 -0.200699" rpy="0 0 0"/>
    <geometry>
      <mesh filename="meshes/Support_roll_servo_L1.stl" scale="0.001 0.001 0.001"/>
    </geometry>
    <material name="silver"/>
    <material/>
  </visual>
  <collision>
    <origin xyz="-0.030628 -0.040148 -0.200699" rpy="0 0 0"/>
    <geometry>
      <mesh filename="meshes/Support_roll_servo_L1.stl" scale="0.001 0.001 0.001"/>
    </geometry>
  </collision>
</link>

<link name="Hip_servo_Pitch_L1">
  <inertial>
    <origin xyz="0.014675874563868638 -0.00849934833873182 0.02448944364464442" rpy="0 0 0"/>
    <mass value="0.0811"/>
    <inertia ixx="2.3417335463269515e-05" iyy="12.961400395210524e-06" izz="1.969636612402693e-05" ixy="2.0523614970348356e-08" iyz="-1.5930335249283921e-07" ixz="-2.7805076826824883e-09"/>
  </inertial>
  <visual>
    <origin xyz="-0.007126 -0.021598 -0.200711" rpy="0 0 0"/>
    <geometry>
      <mesh filename="meshes/Hip_servo_Pitch_L1.stl" scale="0.001 0.001 0.001"/>
    </geometry>
    <material name="silver"/>
    <material/>
  </visual>
  <collision>
    <origin xyz="-0.007126 -0.021598 -0.200711" rpy="0 0 0"/>
    <geometry>
      <mesh filename="meshes/Hip_servo_Pitch_L1.stl" scale="0.001 0.001 0.001"/>
    </geometry>
  </collision>
</link>

<link name="Hip_servo_roll_R1">
  <inertial>
    <origin xyz="-7.753755698614029e-08 0.02042667618526226 -0.011311424755605842" rpy="0 0 0"/>
    <mass value="0.0811"/>
    <inertia ixx="2.3417335463269515e-05" iyy="12.961400395210524e-06" izz="1.969636612402693e-05" ixy="2.0523614970348356e-08" iyz="-1.5930335249283921e-07" ixz="-2.7805076826824883e-09"/>
  </inertial>
  <visual>
    <origin xyz="-0.099128 -0.034373 -0.236699" rpy="0 0 0"/>
    <geometry>
      <mesh filename="meshes/Hip_servo_roll_R1.stl" scale="0.001 0.001 0.001"/>
    </geometry>
    <material name="silver"/>
    <material/>
  </visual>
  <collision>
    <origin xyz="-0.099128 -0.034373 -0.236699" rpy="0 0 0"/>
    <geometry>
      <mesh filename="meshes/Hip_servo_roll_R1.stl" scale="0.001 0.001 0.001"/>
    </geometry>
  </collision>
</link>

<link name="Support_roll_Servo_R1">
  <inertial>
    <origin xyz="-0.008482904734634547 -0.007763870604140438 -7.445276328510442e-07" rpy="0 0 0"/>
    <mass value="0.000991152631600229"/>
    <inertia ixx="5.899142983411561e-08" iyy="1.8810254074607535e-07" izz="2.4162816800247254e-07" ixy="-6.052279683857172e-11" iyz="-1.6902670593133494e-12" ixz="1.5851502979013143e-10"/>
  </inertial>
  <visual>
    <origin xyz="-0.107628 -0.040123 -0.200899" rpy="0 0 0"/>
    <geometry>
      <mesh filename="meshes/Support_roll_Servo_R1.stl" scale="0.001 0.001 0.001"/>
    </geometry>
    <material name="silver"/>
    <material/>
  </visual>
  <collision>
    <origin xyz="-0.107628 -0.040123 -0.200899" rpy="0 0 0"/>
    <geometry>
      <mesh filename="meshes/Support_roll_Servo_R1.stl" scale="0.001 0.001 0.001"/>
    </geometry>
  </collision>
</link>

<link name="Hip_servo_Pitch_R1">
  <inertial>
    <origin xyz="-0.014676502879000491 -0.008499671379272359 0.024488710964318067" rpy="0 0 0"/>
     <mass value="0.0811"/>
    <inertia ixx="2.3417335463269515e-05" iyy="12.961400395210524e-06" izz="1.969636612402693e-05" ixy="2.0523614970348356e-08" iyz="-1.5930335249283921e-07" ixz="-2.7805076826824883e-09"/>
  </inertial>
  <visual>
    <origin xyz="-0.114126 -0.021593 -0.200886" rpy="0 0 0"/>
    <geometry>
      <mesh filename="meshes/Hip_servo_Pitch_R1.stl" scale="0.001 0.001 0.001"/>
    </geometry>
    <material name="silver"/>
    <material/>
  </visual>
  <collision>
    <origin xyz="-0.114126 -0.021593 -0.200886" rpy="0 0 0"/>
    <geometry>
      <mesh filename="meshes/Hip_servo_Pitch_R1.stl" scale="0.001 0.001 0.001"/>
    </geometry>
  </collision>
</link>

<link name="side_attach_L_hip1">
  <inertial>
    <origin xyz="0.014999692096273623 -0.0030449648531452583 -0.0129790855107213" rpy="0 0 0"/>
    <mass value="0.0051821405505521004"/>
    <inertia ixx="6.678809461064129e-07" iyy="1.5448767594578657e-06" izz="9.305088933269494e-07" ixy="1.376428539288238e-20" iyz="2.639983998775246e-08" ixz="-4.0657581468206416e-20"/>
  </inertial>
  <visual>
    <origin xyz="-0.007126 0.001902 -0.241011" rpy="0 0 0"/>
    <geometry>
      <mesh filename="meshes/side_attach_L_hip1.stl" scale="0.001 0.001 0.001"/>
    </geometry>
    <material name="silver"/>
    <material/>
  </visual>
  <collision>
    <origin xyz="-0.007126 0.001902 -0.241011" rpy="0 0 0"/>
    <geometry>
      <mesh filename="meshes/side_attach_L_hip1.stl" scale="0.001 0.001 0.001"/>
    </geometry>
  </collision>
</link>

<link name="side_attach_R_hip1">
  <inertial>
    <origin xyz="0.014999679588596604 -0.0030449576998069347 -0.012979818191048487" rpy="0 0 0"/>
    <mass value="0.0051821405505521004"/>
    <inertia ixx="6.678809461064129e-07" iyy="1.5448767594578115e-06" izz="9.305088933269325e-07" ixy="4.1081097941833566e-20" iyz="2.6399839987756695e-08" ixz="-5.421010862427522e-20"/>
  </inertial>
  <visual>
    <origin xyz="-0.084126 0.001907 -0.241186" rpy="0 0 0"/>
    <geometry>
      <mesh filename="meshes/side_attach_R_hip1.stl" scale="0.001 0.001 0.001"/>
    </geometry>
    <material name="silver"/>
    <material/>
  </visual>
  <collision>
    <origin xyz="-0.084126 0.001907 -0.241186" rpy="0 0 0"/>
    <geometry>
      <mesh filename="meshes/side_attach_R_hip1.stl" scale="0.001 0.001 0.001"/>
    </geometry>
  </collision>
</link>

<link name="Horn_L_pitch1">
  <inertial>
    <origin xyz="0.0012521355878538712 4.865593969827914e-07 4.813353695898304e-07" rpy="0 0 0"/>
    <mass value="0.0010452069679460242"/>
    <inertia ixx="5.912619983875389e-08" iyy="3.074557111910957e-08" izz="3.074619929578471e-08" ixy="-1.0727354639620493e-17" iyz="-9.826429221097138e-18" ixz="2.9483977007094004e-13"/>
  </inertial>
  <visual>
    <origin xyz="-0.041376 -0.013098 -0.236511" rpy="0 0 0"/>
    <geometry>
      <mesh filename="meshes/Horn_L_pitch1.stl" scale="0.001 0.001 0.001"/>
    </geometry>
    <material name="silver"/>
    <material/>
  </visual>
  <collision>
    <origin xyz="-0.041376 -0.013098 -0.236511" rpy="0 0 0"/>
    <geometry>
      <mesh filename="meshes/Horn_L_pitch1.stl" scale="0.001 0.001 0.001"/>
    </geometry>
  </collision>
</link>

<link name="Horn_R_pitch1">
  <inertial>
    <origin xyz="-0.0012527639029847326 4.937225982701299e-07 -2.5134495748591057e-07" rpy="0 0 0"/>
    <mass value="0.0010452069679460242"/>
    <inertia ixx="5.912619983876067e-08" iyy="3.074557111909602e-08" izz="3.0746199295786403e-08" ixy="-1.072682524402846e-17" iyz="9.827276254044393e-18" ixz="-2.9483976837687415e-13"/>
  </inertial>
  <visual>
    <origin xyz="-0.079876 -0.013093 -0.236686" rpy="0 0 0"/>
    <geometry>
      <mesh filename="meshes/Horn_R_pitch1.stl" scale="0.001 0.001 0.001"/>
    </geometry>
    <material name="silver"/>
    <material/>
  </visual>
  <collision>
    <origin xyz="-0.079876 -0.013093 -0.236686" rpy="0 0 0"/>
    <geometry>
      <mesh filename="meshes/Horn_R_pitch1.stl" scale="0.001 0.001 0.001"/>
    </geometry>
  </collision>
</link>

<link name="Hip_Knee_bracket_L1">
  <inertial>
    <origin xyz="0.021249692096275977 4.865643284390764e-07 -0.033829438471636136" rpy="0 0 0"/>
    <mass value="0.009175751935708147"/>
    <inertia ixx="4.594487188322037e-06" iyy="8.003394278945509e-06" izz="4.152987321468783e-06" ixy="4.1928130889087867e-20" iyz="5.421010862427522e-20" ixz="6.301925127571995e-19"/>
  </inertial>
  <visual>
    <origin xyz="-0.001376 -0.013098 -0.236511" rpy="0 0 0"/>
    <geometry>
      <mesh filename="meshes/Hip_Knee_bracket_L1.stl" scale="0.001 0.001 0.001"/>
    </geometry>
    <material name="silver"/>
    <material/>
  </visual>
  <collision>
    <origin xyz="-0.001376 -0.013098 -0.236511" rpy="0 0 0"/>
    <geometry>
      <mesh filename="meshes/Hip_Knee_bracket_L1.stl" scale="0.001 0.001 0.001"/>
    </geometry>
  </collision>
</link>

<link name="Hip_Knee_Backet_R1">
  <inertial>
    <origin xyz="-0.021250320411406745 4.937176672527299e-07 -0.03383017115196263" rpy="0 0 0"/>
    <mass value="0.009175751935708147"/>
    <inertia ixx="4.5944871883218746e-06" iyy="8.0033942789454e-06" izz="4.15298732146876e-06" ixy="6.098637220230962e-20" iyz="9.486769009248164e-20" ixz="-6.2341624917916505e-19"/>
  </inertial>
  <visual>
    <origin xyz="-0.119876 -0.013093 -0.236686" rpy="0 0 0"/>
    <geometry>
      <mesh filename="meshes/Hip_Knee_Backet_R1.stl" scale="0.001 0.001 0.001"/>
    </geometry>
    <material name="silver"/>
    <material/>
  </visual>
  <collision>
    <origin xyz="-0.119876 -0.013093 -0.236686" rpy="0 0 0"/>
    <geometry>
      <mesh filename="meshes/Hip_Knee_Backet_R1.stl" scale="0.001 0.001 0.001"/>
    </geometry>
  </collision>
</link>

<link name="Knee_attach_R1">
  <inertial>
    <origin xyz="-0.006000320411404053 0.005000493717670246 -0.002398275087053814" rpy="0 0 0"/>
    <mass value="0.004096604584621629"/>
    <inertia ixx="2.3788320348527283e-07" iyy="5.967941100390168e-07" izz="8.00202789891466e-07" ixy="5.082197683525802e-21" iyz="1.2027867851011065e-19" ixz="0.0"/>
  </inertial>
  <visual>
    <origin xyz="-0.104626 -0.008093 -0.177786" rpy="0 0 0"/>
    <geometry>
      <mesh filename="meshes/Knee_attach_R1.stl" scale="0.001 0.001 0.001"/>
    </geometry>
    <material name="silver"/>
    <material/>
  </visual>
  <collision>
    <origin xyz="-0.104626 -0.008093 -0.177786" rpy="0 0 0"/>
    <geometry>
      <mesh filename="meshes/Knee_attach_R1.stl" scale="0.001 0.001 0.001"/>
    </geometry>
  </collision>
</link>

<link name="Knee_attach_L1">
  <inertial>
    <origin xyz="0.005999692096272949 0.0050004865643309675 -0.002397542406727099" rpy="0 0 0"/>
    <mass value="0.004096604584621629"/>
    <inertia ixx="2.3788320348529994e-07" iyy="5.967941100390168e-07" izz="8.002027898914601e-07" ixy="4.446922973085077e-21" iyz="1.2366681029912785e-19" ixz="-3.3881317890172014e-21"/>
  </inertial>
  <visual>
    <origin xyz="-0.016626 -0.008098 -0.177611" rpy="0 0 0"/>
    <geometry>
      <mesh filename="meshes/Knee_attach_L1.stl" scale="0.001 0.001 0.001"/>
    </geometry>
    <material name="silver"/>
    <material/>
  </visual>
  <collision>
    <origin xyz="-0.016626 -0.008098 -0.177611" rpy="0 0 0"/>
    <geometry>
      <mesh filename="meshes/Knee_attach_L1.stl" scale="0.001 0.001 0.001"/>
    </geometry>
  </collision>
</link>

<link name="Knee_servo_Pitch_R1">
  <inertial>
    <origin xyz="-0.014676502879000353 0.008500658814608045 -0.024489216296418842" rpy="0 0 0"/>
    <mass value="0.0811"/>
    <inertia ixx="2.3417335463269515e-05" iyy="12.961400395210524e-06" izz="1.969636612402693e-05" ixy="2.0523614970348356e-08" iyz="-1.5930335249283921e-07" ixz="-2.7805076826824883e-09"/>
  </inertial>
  <visual>
    <origin xyz="-0.113626 -0.004593 -0.171986" rpy="0 0 0"/>
    <geometry>
      <mesh filename="meshes/Knee_servo_Pitch_R1.stl" scale="0.001 0.001 0.001"/>
    </geometry>
    <material name="silver"/>
    <material/>
  </visual>
  <collision>
    <origin xyz="-0.113626 -0.004593 -0.171986" rpy="0 0 0"/>
    <geometry>
      <mesh filename="meshes/Knee_servo_Pitch_R1.stl" scale="0.001 0.001 0.001"/>
    </geometry>
  </collision>
</link>

<link name="Knee_servo_Pitch_L1">
  <inertial>
    <origin xyz="0.014675874563868638 0.008500321467389181 -0.024488483616092294" rpy="0 0 0"/>
    <mass value="0.0811"/>
    <inertia ixx="2.3417335463269515e-05" iyy="12.961400395210524e-06" izz="1.969636612402693e-05" ixy="2.0523614970348356e-08" iyz="-1.5930335249283921e-07" ixz="-2.7805076826824883e-09"/>
  </inertial>
  <visual>
    <origin xyz="-0.007626 -0.004598 -0.171811" rpy="0 0 0"/>
    <geometry>
      <mesh filename="meshes/Knee_servo_Pitch_L1.stl" scale="0.001 0.001 0.001"/>
    </geometry>
    <material name="silver"/>
    <material/>
  </visual>
  <collision>
    <origin xyz="-0.007626 -0.004598 -0.171811" rpy="0 0 0"/>
    <geometry>
      <mesh filename="meshes/Knee_servo_Pitch_L1.stl" scale="0.001 0.001 0.001"/>
    </geometry>
  </collision>
</link>

<link name="Horn_knee_R1">
  <inertial>
    <origin xyz="-0.001252763902984913 4.937226001661826e-07 -2.5134495568179815e-07" rpy="0 0 0"/>
    <mass value="0.0010452069679460242"/>
    <inertia ixx="5.9126199838750504e-08" iyy="3.074557111909602e-08" izz="3.0746199295785556e-08" ixy="-1.0727037002265273e-17" iyz="9.827276254044393e-18" ixz="-2.9483977007094004e-13"/>
  </inertial>
  <visual>
    <origin xyz="-0.079376 -0.013093 -0.136186" rpy="0 0 0"/>
    <geometry>
      <mesh filename="meshes/Horn_knee_R1.stl" scale="0.001 0.001 0.001"/>
    </geometry>
    <material name="silver"/>
    <material/>
  </visual>
  <collision>
    <origin xyz="-0.079376 -0.013093 -0.136186" rpy="0 0 0"/>
    <geometry>
      <mesh filename="meshes/Horn_knee_R1.stl" scale="0.001 0.001 0.001"/>
    </geometry>
  </collision>
</link>

<link name="horn_knee_L1">
  <inertial>
    <origin xyz="0.002252135587853879 4.865593970278942e-07 4.813353710608759e-07" rpy="0 0 0"/>
    <mass value="0.0010452069679460242"/>
    <inertia ixx="5.9126199838747116e-08" iyy="3.0745571119099405e-08" izz="3.074619929578513e-08" ixy="-1.0727037002265273e-17" iyz="-9.827276254044393e-18" ixz="2.94839770917973e-13"/>
  </inertial>
  <visual>
    <origin xyz="-0.040776 -0.013098 -0.136011" rpy="0 0 0"/>
    <geometry>
      <mesh filename="meshes/horn_knee_L1.stl" scale="0.001 0.001 0.001"/>
    </geometry>
    <material name="silver"/>
    <material/>
  </visual>
  <collision>
    <origin xyz="-0.040776 -0.013098 -0.136011" rpy="0 0 0"/>
    <geometry>
      <mesh filename="meshes/horn_knee_L1.stl" scale="0.001 0.001 0.001"/>
    </geometry>
  </collision>
</link>

<link name="Knee_Foot_bracket_R1">
  <inertial>
    <origin xyz="-0.020750320411406342 -0.005736828540610742 -0.045869017981759186" rpy="0 0 0"/>
    <mass value="0.01132882807356771"/>
    <inertia ixx="1.2028771165940581e-05" iyy="1.55864745617426e-05" izz="5.285440237642322e-06" ixy="-2.6359665318553827e-18" iyz="3.3191643722885005e-07" ixz="-4.824699667560495e-18"/>
  </inertial>
  <visual>
    <origin xyz="-0.119376 -0.013093 -0.136186" rpy="0 0 0"/>
    <geometry>
      <mesh filename="meshes/Knee_Foot_bracket_R1.stl" scale="0.001 0.001 0.001"/>
    </geometry>
    <material name="silver"/>
    <material/>
  </visual>
  <collision>
    <origin xyz="-0.119376 -0.013093 -0.136186" rpy="0 0 0"/>
    <geometry>
      <mesh filename="meshes/Knee_Foot_bracket_R1.stl" scale="0.001 0.001 0.001"/>
    </geometry>
  </collision>
</link>

<link name="Knee_Foot_Bracket_L1">
  <inertial>
    <origin xyz="0.02074969209627193 -0.005736835693952584 -0.04586828530143351" rpy="0 0 0"/>
    <mass value="0.01132882807356771"/>
    <inertia ixx="1.2028771165943156e-05" iyy="1.558647456173733e-05" izz="5.285440237642529e-06" ixy="-1.0532854699107225e-18" iyz="3.319164372288721e-07" ixz="-4.360525612465138e-18"/>
  </inertial>
  <visual>
    <origin xyz="-0.001876 -0.013098 -0.136011" rpy="0 0 0"/>
    <geometry>
      <mesh filename="meshes/Knee_Foot_Bracket_L1.stl" scale="0.001 0.001 0.001"/>
    </geometry>
    <material name="silver"/>
    <material/>
  </visual>
  <collision>
    <origin xyz="-0.001876 -0.013098 -0.136011" rpy="0 0 0"/>
    <geometry>
      <mesh filename="meshes/Knee_Foot_Bracket_L1.stl" scale="0.001 0.001 0.001"/>
    </geometry>
  </collision>
</link>

<link name="Foot_servo_pitch_L1">
  <inertial>
    <origin xyz="-0.02042649037132176 6.579111523682263e-07 0.011310766149735293" rpy="0 0 0"/>
    <mass value="0.0811"/>
    <inertia ixx="2.3417335463269515e-05" iyy="12.961400395210524e-06" izz="1.969636612402693e-05" ixy="2.0523614970348356e-08" iyz="-1.5930335249283921e-07" ixz="-2.7805076826824883e-09"/>
  </inertial>
  <visual>
    <origin xyz="-0.043376 -0.012598 -0.036013" rpy="0 0 0"/>
    <geometry>
      <mesh filename="meshes/Foot_servo_pitch_L1.stl" scale="0.001 0.001 0.001"/>
    </geometry>
    <material name="silver"/>
    <material/>
  </visual>
  <collision>
    <origin xyz="-0.043376 -0.012598 -0.036013" rpy="0 0 0"/>
    <geometry>
      <mesh filename="meshes/Foot_servo_pitch_L1.stl" scale="0.001 0.001 0.001"/>
    </geometry>
  </collision>
</link>

<link name="Horn_foot_L1">
  <inertial>
    <origin xyz="-0.08656475139530725 -0.03292450718085519 0.04509873110119793" rpy="0 0 0"/>
    <mass value="0.0010452069679460242"/>
    <inertia ixx="5.912619983874902e-08" iyy="3.074557111909665e-08" izz="3.074619929578468e-08" ixy="-1.0726944358036667e-17" iyz="9.827223314485189e-18" ixz="-2.9483976968712824e-13"/>
  </inertial>
  <visual>
    <origin xyz="-0.088888 -0.045523 0.009086" rpy="0 0 0"/>
    <geometry>
      <mesh filename="meshes/Horn_foot_L1.stl" scale="0.001 0.001 0.001"/>
    </geometry>
    <material name="silver"/>
    <material/>
  </visual>
  <collision>
    <origin xyz="-0.088888 -0.045523 0.009086" rpy="0 0 0"/>
    <geometry>
      <mesh filename="meshes/Horn_foot_L1.stl" scale="0.001 0.001 0.001"/>
    </geometry>
  </collision>
</link>

<link name="Foot_servo_pitch_R1">
  <inertial>
    <origin xyz="0.02042586205619032 3.348706169078314e-07 0.01131103346940917" rpy="0 0 0"/>
    <mass value="0.0811"/>
    <inertia ixx="2.3417335463269515e-05" iyy="12.961400395210524e-06" izz="1.969636612402693e-05" ixy="2.0523614970348356e-08" iyz="-1.5930335249283921e-07" ixz="-2.7805076826824883e-09"/>
  </inertial>
  <visual>
    <origin xyz="-0.077876 -0.012593 -0.036187" rpy="0 0 0"/>
    <geometry>
      <mesh filename="meshes/Foot_servo_pitch_R1.stl" scale="0.001 0.001 0.001"/>
    </geometry>
    <material name="silver"/>
    <material/>
  </visual>
  <collision>
    <origin xyz="-0.077876 -0.012593 -0.036187" rpy="0 0 0"/>
    <geometry>
      <mesh filename="meshes/Foot_servo_pitch_R1.stl" scale="0.001 0.001 0.001"/>
    </geometry>
  </collision>
</link>

<link name="horn_foot_R1">
  <inertial>
    <origin xyz="0.08673912308017687 -0.07717550003737624 0.045093998420873006" rpy="0 0 0"/>
    <mass value="0.0010452069679460242"/>
    <inertia ixx="5.9126199838749445e-08" iyy="3.0745571119099405e-08" izz="3.074619929578386e-08" ixy="-1.0728095793449341e-17" iyz="-9.827064495807579e-18" ixz="2.94839770917973e-13"/>
  </inertial>
  <visual>
    <origin xyz="-0.032189 -0.089769 0.008907" rpy="0 0 0"/>
    <geometry>
      <mesh filename="meshes/horn_foot_R1.stl" scale="0.001 0.001 0.001"/>
    </geometry>
    <material name="silver"/>
    <material/>
  </visual>
  <collision>
    <origin xyz="-0.032189 -0.089769 0.008907" rpy="0 0 0"/>
    <geometry>
      <mesh filename="meshes/horn_foot_R1.stl" scale="0.001 0.001 0.001"/>
    </geometry>
  </collision>
</link>

<link name="side_attach_foot_L1">
  <inertial>
    <origin xyz="0.01499969209627203 -0.003044958603260741 -0.02102070469489966" rpy="0 0 0"/>
    <mass value="0.0051821405505521004"/>
    <inertia ixx="6.678809461064637e-07" iyy="1.5448767594579199e-06" izz="9.305088933269494e-07" ixy="1.7470054537119944e-20" iyz="-2.6399839987736366e-08" ixz="-4.0657581468206416e-20"/>
  </inertial>
  <visual>
    <origin xyz="-0.007626 0.002402 -0.065513" rpy="0 0 0"/>
    <geometry>
      <mesh filename="meshes/side_attach_foot_L1.stl" scale="0.001 0.001 0.001"/>
    </geometry>
    <material name="silver"/>
    <material/>
  </visual>
  <collision>
    <origin xyz="-0.007626 0.002402 -0.065513" rpy="0 0 0"/>
    <geometry>
      <mesh filename="meshes/side_attach_foot_L1.stl" scale="0.001 0.001 0.001"/>
    </geometry>
  </collision>
</link>

<link name="side_attach_foot_R1">
  <inertial>
    <origin xyz="0.014999679588593176 -0.0030449514499178132 -0.021020437375226145" rpy="0 0 0"/>
    <mass value="0.0051821405505521004"/>
    <inertia ixx="6.67880946106462e-07" iyy="1.5448767594579334e-06" izz="9.305088933269528e-07" ixy="6.098637220230962e-20" iyz="-2.6399839987733613e-08" ixz="-4.743384504624082e-20"/>
  </inertial>
  <visual>
    <origin xyz="-0.083626 0.002407 -0.065687" rpy="0 0 0"/>
    <geometry>
      <mesh filename="meshes/side_attach_foot_R1.stl" scale="0.001 0.001 0.001"/>
    </geometry>
    <material name="silver"/>
    <material/>
  </visual>
  <collision>
    <origin xyz="-0.083626 0.002407 -0.065687" rpy="0 0 0"/>
    <geometry>
      <mesh filename="meshes/side_attach_foot_R1.stl" scale="0.001 0.001 0.001"/>
    </geometry>
  </collision>
</link>

<link name="Washer_31">
  <inertial>
    <origin xyz="-3.079033827589617e-07 -0.0009495071857869766 -2.702198959314561e-07" rpy="0 0 0"/>
    <mass value="0.0001569470040624276"/>
    <inertia ixx="2.0953979171312804e-09" iyy="4.096365919140425e-09" izz="2.0953977827867066e-09" ixy="3.970466940254533e-23" iyz="2.6469779601696886e-23" ixz="-2.6469779601696886e-23"/>
  </inertial>
  <visual>
    <origin xyz="-0.022626 0.008202 -0.036013" rpy="0 0 0"/>
    <geometry>
      <mesh filename="meshes/Washer_31.stl" scale="0.001 0.001 0.001"/>
    </geometry>
    <material name="silver"/>
    <material/>
  </visual>
  <collision>
    <origin xyz="-0.022626 0.008202 -0.036013" rpy="0 0 0"/>
    <geometry>
      <mesh filename="meshes/Washer_31.stl" scale="0.001 0.001 0.001"/>
    </geometry>
  </collision>
</link>

<link name="Washer_41">
  <inertial>
    <origin xyz="-3.2041106155789034e-07 -0.0009495000324434687 -2.900222124957441e-09" rpy="0 0 0"/>
    <mass value="0.0001569470040624276"/>
    <inertia ixx="2.0953979171312275e-09" iyy="4.0963659191399485e-09" izz="2.0953977827866404e-09" ixy="1.3234889800848443e-22" iyz="2.6469779601696886e-23" ixz="1.0587911840678754e-22"/>
  </inertial>
  <visual>
    <origin xyz="-0.098626 0.008207 -0.036187" rpy="0 0 0"/>
    <geometry>
      <mesh filename="meshes/Washer_41.stl" scale="0.001 0.001 0.001"/>
    </geometry>
    <material name="silver"/>
    <material/>
  </visual>
  <collision>
    <origin xyz="-0.098626 0.008207 -0.036187" rpy="0 0 0"/>
    <geometry>
      <mesh filename="meshes/Washer_41.stl" scale="0.001 0.001 0.001"/>
    </geometry>
  </collision>
</link>

<link name="support_attach_foot_R1">
  <inertial>
    <origin xyz="-0.014980904734635064 0.010766135645748173 1.250523819568139e-05" rpy="0 0 0"/>
    <mass value="0.000991152631600229"/>
    <inertia ixx="5.8991429834111377e-08" iyy="1.8810254074607874e-07" izz="2.4162816800247254e-07" ixy="-6.052279683264249e-11" iyz="-1.690267058889833e-12" ixz="1.585150297816611e-10"/>
  </inertial>
  <visual>
    <origin xyz="-0.113626 -0.021093 -0.071987" rpy="0 0 0"/>
    <geometry>
      <mesh filename="meshes/support_attach_foot_R1.stl" scale="0.001 0.001 0.001"/>
    </geometry>
    <material name="silver"/>
    <material/>
  </visual>
  <collision>
    <origin xyz="-0.113626 -0.021093 -0.071987" rpy="0 0 0"/>
    <geometry>
      <mesh filename="meshes/support_attach_foot_R1.stl" scale="0.001 0.001 0.001"/>
    </geometry>
  </collision>
</link>

<link name="support_attach_foot_L1">
  <inertial>
    <origin xyz="0.015019095265367776 0.010766128492404603 -1.3494761805218913e-05" rpy="0 0 0"/>
    <mass value="0.000991152631600229"/>
    <inertia ixx="5.899142983411053e-08" iyy="1.8810254074607705e-07" izz="2.416281680024772e-07" ixy="-6.052279683984227e-11" iyz="-1.6902670580428e-12" ixz="1.58515029785261e-10"/>
  </inertial>
  <visual>
    <origin xyz="-0.007626 -0.021098 -0.071813" rpy="0 0 0"/>
    <geometry>
      <mesh filename="meshes/support_attach_foot_L1.stl" scale="0.001 0.001 0.001"/>
    </geometry>
    <material name="silver"/>
    <material/>
  </visual>
  <collision>
    <origin xyz="-0.007626 -0.021098 -0.071813" rpy="0 0 0"/>
    <geometry>
      <mesh filename="meshes/support_attach_foot_L1.stl" scale="0.001 0.001 0.001"/>
    </geometry>
  </collision>
</link>

<link name="foot_Servo_roll_R1">
  <inertial>
    <origin xyz="0.008500252656323384 0.01467668243515189 -0.02448910225051438" rpy="0 0 0"/>
    <mass value="0.0811"/>
    <inertia ixx="2.3417335463269515e-05" iyy="12.961400395210524e-06" izz="1.969636612402693e-05" ixy="2.0523614970348356e-08" iyz="-1.5930335249283921e-07" ixz="-2.7805076826824883e-09"/>
  </inertial>
  <visual>
    <origin xyz="-0.090128 -0.039623 -0.072" rpy="0 0 0"/>
    <geometry>
      <mesh filename="meshes/foot_Servo_roll_R1.stl" scale="0.001 0.001 0.001"/>
    </geometry>
    <material name="silver"/>
    <material/>
  </visual>
  <collision>
    <origin xyz="-0.090128 -0.039623 -0.072" rpy="0 0 0"/>
    <geometry>
      <mesh filename="meshes/foot_Servo_roll_R1.stl" scale="0.001 0.001 0.001"/>
    </geometry>
  </collision>
</link>

<link name="foot_servo_roll_L1">
  <inertial>
    <origin xyz="0.008500252656324985 0.014676675281807584 -0.024489102250515565" rpy="0 0 0"/>
    <mass value="0.0811"/>
    <inertia ixx="2.3417335463269515e-05" iyy="12.961400395210524e-06" izz="1.969636612402693e-05" ixy="2.0523614970348356e-08" iyz="-1.5930335249283921e-07" ixz="-2.7805076826824883e-09"/>
  </inertial>
  <visual>
    <origin xyz="-0.014128 -0.039628 -0.0718" rpy="0 0 0"/>
    <geometry>
      <mesh filename="meshes/foot_servo_roll_L1.stl" scale="0.001 0.001 0.001"/>
    </geometry>
    <material name="silver"/>
    <material/>
  </visual>
  <collision>
    <origin xyz="-0.014128 -0.039628 -0.0718" rpy="0 0 0"/>
    <geometry>
      <mesh filename="meshes/foot_servo_roll_L1.stl" scale="0.001 0.001 0.001"/>
    </geometry>
  </collision>
</link>

<link name="foot_connect_R1">
  <inertial>
    <origin xyz="8.755939616411634e-08 -0.02418545026519283 -0.018933957152685102" rpy="0 0 0"/>
    <mass value="0.009163335973748653"/>
    <inertia ixx="5.388156082317761e-06" iyy="2.0604137855260025e-06" izz="4.098092484132955e-06" ixy="-3.4389537658524594e-19" iyz="3.226179646354344e-08" ixz="-3.2221133313553585e-18"/>
  </inertial>
  <visual>
    <origin xyz="-0.098628 -0.033873 -0.0362" rpy="0 0 0"/>
    <geometry>
      <mesh filename="meshes/foot_connect_R1.stl" scale="0.001 0.001 0.001"/>
    </geometry>
    <material name="silver"/>
    <material/>
  </visual>
  <collision>
    <origin xyz="-0.098628 -0.033873 -0.0362" rpy="0 0 0"/>
    <geometry>
      <mesh filename="meshes/foot_connect_R1.stl" scale="0.001 0.001 0.001"/>
    </geometry>
  </collision>
</link>

<link name="foot_connect_L1">
  <inertial>
    <origin xyz="8.755939907845178e-08 -0.02418545741853705 -0.018933957152686056" rpy="0 0 0"/>
    <mass value="0.009163335973748653"/>
    <inertia ixx="5.388156082317786e-06" iyy="2.060413785525978e-06" izz="4.09809248413296e-06" ixy="-1.6855955650360577e-19" iyz="3.226179646356017e-08" ixz="-3.2534535504037676e-18"/>
  </inertial>
  <visual>
    <origin xyz="-0.022628 -0.033878 -0.036" rpy="0 0 0"/>
    <geometry>
      <mesh filename="meshes/foot_connect_L1.stl" scale="0.001 0.001 0.001"/>
    </geometry>
    <material name="silver"/>
    <material/>
  </visual>
  <collision>
    <origin xyz="-0.022628 -0.033878 -0.036" rpy="0 0 0"/>
    <geometry>
      <mesh filename="meshes/foot_connect_L1.stl" scale="0.001 0.001 0.001"/>
    </geometry>
  </collision>
</link>

<link name="Bush_31">
  <inertial>
    <origin xyz="0.0986256795885939 -0.01442899196504672 -0.036187002900855" rpy="0 0 0"/>
    <mass value="0.00033912761870964644"/>
    <inertia ixx="3.55341069830501e-09" iyy="4.084788845233821e-09" izz="3.5534104748454365e-09" ixy="0.0" iyz="1.4328091698398524e-19" ixz="2.117582368135751e-22"/>
  </inertial>
  <visual>
    <origin xyz="-0.0 -0.0019 -0.072374" rpy="0 0 0"/>
    <geometry>
      <mesh filename="meshes/Bush_31.stl" scale="0.001 0.001 0.001"/>
    </geometry>
    <material name="silver"/>
    <material/>
  </visual>
  <collision>
    <origin xyz="-0.0 -0.0019 -0.072374" rpy="0 0 0"/>
    <geometry>
      <mesh filename="meshes/Bush_31.stl" scale="0.001 0.001 0.001"/>
    </geometry>
  </collision>
</link>

<link name="Bush_41">
  <inertial>
    <origin xyz="0.022625692096272715 -0.014423999118389902 -0.036012270220528525" rpy="0 0 0"/>
    <mass value="0.00033912761870964644"/>
    <inertia ixx="3.553410698305116e-09" iyy="4.084788845233398e-09" izz="3.5534104748462836e-09" ixy="-2.6469779601696886e-23" iyz="1.4328091698398524e-19" ixz="5.293955920339377e-23"/>
  </inertial>
  <visual>
    <origin xyz="-0.0 -0.0019 -0.072025" rpy="0 0 0"/>
    <geometry>
      <mesh filename="meshes/Bush_41.stl" scale="0.001 0.001 0.001"/>
    </geometry>
    <material name="silver"/>
    <material/>
  </visual>
  <collision>
    <origin xyz="-0.0 -0.0019 -0.072025" rpy="0 0 0"/>
    <geometry>
      <mesh filename="meshes/Bush_41.stl" scale="0.001 0.001 0.001"/>
    </geometry>
  </collision>
</link>

<link name="Washer_21">
  <inertial>
    <origin xyz="8.755903861679126e-08 -0.000949506282329789 -3.883859768794018e-07" rpy="0 0 0"/>
    <mass value="0.0001569470040624276"/>
    <inertia ixx="2.0953979171296658e-09" iyy="4.0963659191391015e-09" izz="2.0953977827866404e-09" ixy="5.624828165360588e-23" iyz="0.0" ixz="0.0"/>
  </inertial>
  <visual>
    <origin xyz="-0.022128 0.007627 -0.236499" rpy="0 0 0"/>
    <geometry>
      <mesh filename="meshes/Washer_21.stl" scale="0.001 0.001 0.001"/>
    </geometry>
    <material name="silver"/>
    <material/>
  </visual>
  <collision>
    <origin xyz="-0.022128 0.007627 -0.236499" rpy="0 0 0"/>
    <geometry>
      <mesh filename="meshes/Washer_21.stl" scale="0.001 0.001 0.001"/>
    </geometry>
  </collision>
</link>

<link name="Foot_L1">
  <inertial>
    <origin xyz="-2.7052128486727833e-05 0.007324772290066046 -0.0006236210593121259" rpy="0 0 0"/>
    <mass value="0.11874731720777594"/>
    <inertia ixx="0.00013504403572545478" iyy="5.5253122397327985e-05" izz="0.00018972335778322334" ixy="1.6680131596703596e-08" iyz="2.294744148063528e-06" ixz="-1.2134276637682498e-09"/>
  </inertial>
  <visual>
    <origin xyz="-0.016628 0.002622 -0.002" rpy="0 0 0"/>
    <geometry>
      <mesh filename="meshes/Foot_L1.stl" scale="0.001 0.001 0.001"/>
    </geometry>
    <material name="silver"/>
    <material/>
  </visual>
  <collision>
    <origin xyz="-0.016628 0.002622 -0.002" rpy="0 0 0"/>
    <geometry>
      <mesh filename="meshes/Foot_L1.stl" scale="0.001 0.001 0.001"/>
    </geometry>
  </collision>
</link>

<link name="Foot_R1">
  <inertial>
    <origin xyz="0.012027451028017819 -0.01725251116732917 -0.0007467666233469173" rpy="0 0 0"/>
    <mass value="0.12955381074460537"/>
    <inertia ixx="0.00014571037521278116" iyy="6.0318526185315115e-05" izz="0.00020541185133327164" ixy="-1.6849622382276346e-08" iyz="2.3689601189101116e-06" ixz="1.2527184422173737e-09"/>
  </inertial>
  <visual>
    <origin xyz="-0.092628 -0.022373 -0.0022" rpy="0 0 0"/>
    <geometry>
      <mesh filename="meshes/Foot_R1.stl" scale="0.001 0.001 0.001"/>
    </geometry>
    <material name="silver"/>
    <material/>
  </visual>
  <collision>
    <origin xyz="-0.092628 -0.022373 -0.0022" rpy="0 0 0"/>
    <geometry>
      <mesh filename="meshes/Foot_R1.stl" scale="0.001 0.001 0.001"/>
    </geometry>
  </collision>
</link>
<joint name="base_joint" type="fixed">
  <!--origin xyz="-0.07139043603557767 -0.19954551899156534 0.325032870177832" rpy="0 0 0"/-->
  <origin xyz="0.05139043603557767 -0.00009954551899156534 0.335032870177832" rpy="0 0 0"/>
  <parent link="base_link"/>
  <child link="base_box"/>
</joint>

<joint name="Rigid_1" type="fixed">
  <origin xyz="0.060628 0.038873 0.308999" rpy="0 0 0"/>
  <parent link="base_link"/>
  <child link="connect_link_v11"/>
</joint>

<joint name="Rigid_2" type="fixed">
  <origin xyz="-0.025 -0.006 -0.0065" rpy="0 0 0"/>
  <parent link="connect_link_v11"/>
  <child link="Hip_servo_Yaw_L1"/>
</joint>

<joint name="Rigid_3" type="fixed">
  <origin xyz="0.025 -0.006 -0.0065" rpy="0 0 0"/>
  <parent link="connect_link_v11"/>
  <child link="Hip_servo_Yaw__R_1"/>
</joint>

<joint name="Rigid_4" type="fixed">
  <origin xyz="0.0 0.0 -0.032" rpy="0 0 0"/>
  <parent link="Hip_servo_Yaw_L1"/>
  <child link="connect_link_21"/>
</joint>

<joint name="Rigid_5" type="fixed">
  <origin xyz="0.025 0.006 -0.0015" rpy="0 0 0"/>
  <parent link="connect_link_21"/>
  <child link="support_link1"/>
</joint>

<joint name="Revolute_12" type="continuous">
  <origin xyz="-0.0135 -0.0225 -0.037" rpy="0 0 0"/>
  <parent link="Hip_servo_Yaw_L1"/>
  <child link="Hip_bracket_yaw_L_v11"/>
  <axis xyz="-0.0 0.0 -1.0"/>
</joint>
<transmission name="Revolute_12_tran">
  <type>transmission_interface/SimpleTransmission</type>
  <joint name="Revolute_12">
    <hardwareInterface>PositionJointInterface</hardwareInterface>
  </joint>
  <actuator name="Revolute_12_actr">
    <hardwareInterface>PositionJointInterface</hardwareInterface>
    <mechanicalReduction>1</mechanicalReduction>
  </actuator>
</transmission>

<joint name="Revolute_14" type="continuous">
  <origin xyz="0.0135 -0.0225 -0.0368" rpy="0 0 0"/>
  <parent link="Hip_servo_Yaw__R_1"/>
  <child link="Hip_Bracket_yaw_R1"/>
  <axis xyz="-0.0 0.0 -1.0"/>
</joint>
<transmission name="Revolute_14_tran">
  <type>transmission_interface/SimpleTransmission</type>
  <joint name="Revolute_14">
    <hardwareInterface>PositionJointInterface</hardwareInterface>
  </joint>
  <actuator name="Revolute_14_actr">
    <hardwareInterface>PositionJointInterface</hardwareInterface>
    <mechanicalReduction>1</mechanicalReduction>
  </actuator>
</transmission>

<joint name="Rigid_15" type="fixed">
  <origin xyz="-0.022128 -0.236498 0.013626" rpy="0 0 0"/>
  <parent link="Hip_bracket_yaw_L_v11"/>
  <child link="Bush_2_1"/>
</joint>

<joint name="Rigid_16" type="fixed">
  <origin xyz="0.077128 0.236699 0.013626" rpy="0 0 0"/>
  <parent link="Hip_Bracket_yaw_R1"/>
  <child link="Bush_1_v11"/>
</joint>

<joint name="Rigid_17" type="fixed">
  <origin xyz="0.022 -0.247072 -0.279325" rpy="0 0 0"/>
  <parent link="Bush_1_v11"/>
  <child link="Washer_11"/>
</joint>

<joint name="Revolute_42" type="continuous">
  <origin xyz="-0.022128 -0.236498 -0.034374" rpy="0 0 0"/>
  <parent link="Hip_bracket_yaw_L_v11"/>
  <child link="Hip_servo_roll_L1"/>
  <axis xyz="-0.0 -1.0 -0.0"/>
</joint>
<transmission name="Revolute_42_tran">
  <type>transmission_interface/SimpleTransmission</type>
  <joint name="Revolute_42">
    <hardwareInterface>PositionJointInterface</hardwareInterface>
  </joint>
  <actuator name="Revolute_42_actr">
    <hardwareInterface>PositionJointInterface</hardwareInterface>
    <mechanicalReduction>1</mechanicalReduction>
  </actuator>
</transmission>

<joint name="Rigid_43" type="fixed">
  <origin xyz="0.030628 0.266273 -0.030426" rpy="0 0 0"/>
  <parent link="Hip_servo_roll_L1"/>
  <child link="Support_roll_servo_L1"/>
</joint>

<joint name="Rigid_44" type="fixed">
  <origin xyz="-0.023502 -0.01855 1.2e-05" rpy="0 0 0"/>
  <parent link="Support_roll_servo_L1"/>
  <child link="Hip_servo_Pitch_L1"/>
</joint>

<joint name="Revolute_45" type="continuous">
  <origin xyz="0.0 0.024 -0.029" rpy="0 0 0"/>
  <parent link="Hip_Bracket_yaw_R1"/>
  <child link="Hip_servo_roll_R1"/>
  <axis xyz="-0.0 -1.0 -0.0"/>
</joint>
<transmission name="Revolute_45_tran">
  <type>transmission_interface/SimpleTransmission</type>
  <joint name="Revolute_45">
    <hardwareInterface>PositionJointInterface</hardwareInterface>
  </joint>
  <actuator name="Revolute_45_actr">
    <hardwareInterface>PositionJointInterface</hardwareInterface>
    <mechanicalReduction>1</mechanicalReduction>
  </actuator>
</transmission>

<joint name="Rigid_46" type="fixed">
  <origin xyz="0.0085 0.00575 -0.0358" rpy="0 0 0"/>
  <parent link="Hip_servo_roll_R1"/>
  <child link="Support_roll_Servo_R1"/>
</joint>

<joint name="Rigid_47" type="fixed">
  <origin xyz="0.006498 -0.01853 -1.3e-05" rpy="0 0 0"/>
  <parent link="Support_roll_Servo_R1"/>
  <child link="Hip_servo_Pitch_R1"/>
</joint>

<joint name="Rigid_48" type="fixed">
  <origin xyz="0.0 -0.0235 0.0403" rpy="0 0 0"/>
  <parent link="Hip_servo_Pitch_L1"/>
  <child link="side_attach_L_hip1"/>
</joint>

<joint name="Rigid_49" type="fixed">
  <origin xyz="-0.03 -0.0235 0.0403" rpy="0 0 0"/>
  <parent link="Hip_servo_Pitch_R1"/>
  <child link="side_attach_R_hip1"/>
</joint>

<joint name="Rigid_50" type="fixed">
  <origin xyz="0.03425 -0.0085 0.0358" rpy="0 0 0"/>
  <parent link="Hip_servo_Pitch_L1"/>
  <child link="Horn_L_pitch1"/>
</joint>

<joint name="Rigid_51" type="fixed">
  <origin xyz="-0.03425 -0.0085 0.0358" rpy="0 0 0"/>
  <parent link="Hip_servo_Pitch_R1"/>
  <child link="Horn_R_pitch1"/>
</joint>

<joint name="Revolute_52" type="continuous">
  <origin xyz="-0.00575 -0.0085 0.0358" rpy="0 0 0"/>
  <parent link="Hip_servo_Pitch_L1"/>
  <child link="Hip_Knee_bracket_L1"/>
  <axis xyz="-1.0 0.0 0.0"/>
</joint>
<transmission name="Revolute_52_tran">
  <type>transmission_interface/SimpleTransmission</type>
  <joint name="Revolute_52">
    <hardwareInterface>PositionJointInterface</hardwareInterface>
  </joint>
  <actuator name="Revolute_52_actr">
    <hardwareInterface>PositionJointInterface</hardwareInterface>
    <mechanicalReduction>1</mechanicalReduction>
  </actuator>
</transmission>

<joint name="Revolute_53" type="continuous">
  <origin xyz="0.00575 -0.0085 0.0358" rpy="0 0 0"/>
  <parent link="Hip_servo_Pitch_R1"/>
  <child link="Hip_Knee_Backet_R1"/>
  <axis xyz="1.0 -0.0 0.0"/>
</joint>
<transmission name="Revolute_53_tran">
  <type>transmission_interface/SimpleTransmission</type>
  <joint name="Revolute_53">
    <hardwareInterface>PositionJointInterface</hardwareInterface>
  </joint>
  <actuator name="Revolute_53_actr">
    <hardwareInterface>PositionJointInterface</hardwareInterface>
    <mechanicalReduction>1</mechanicalReduction>
  </actuator>
</transmission>

<joint name="Rigid_54" type="fixed">
  <origin xyz="-0.01525 -0.005 -0.0589" rpy="0 0 0"/>
  <parent link="Hip_Knee_Backet_R1"/>
  <child link="Knee_attach_R1"/>
</joint>

<joint name="Rigid_55" type="fixed">
  <origin xyz="0.01525 -0.005 -0.0589" rpy="0 0 0"/>
  <parent link="Hip_Knee_bracket_L1"/>
  <child link="Knee_attach_L1"/>
</joint>

<joint name="Rigid_56" type="fixed">
  <origin xyz="0.009 -0.0035 -0.0058" rpy="0 0 0"/>
  <parent link="Knee_attach_R1"/>
  <child link="Knee_servo_Pitch_R1"/>
</joint>

<joint name="Rigid_57" type="fixed">
  <origin xyz="-0.009 -0.0035 -0.0058" rpy="0 0 0"/>
  <parent link="Knee_attach_L1"/>
  <child link="Knee_servo_Pitch_L1"/>
</joint>

<joint name="Rigid_58" type="fixed">
  <origin xyz="-0.03425 0.0085 -0.0358" rpy="0 0 0"/>
  <parent link="Knee_servo_Pitch_R1"/>
  <child link="Horn_knee_R1"/>
</joint>

<joint name="Rigid_59" type="fixed">
  <origin xyz="0.03315 0.0085 -0.0358" rpy="0 0 0"/>
  <parent link="Knee_servo_Pitch_L1"/>
  <child link="horn_knee_L1"/>
</joint>

<joint name="Revolute_60" type="continuous">
  <origin xyz="0.00575 0.0085 -0.0358" rpy="0 0 0"/>
  <parent link="Knee_servo_Pitch_R1"/>
  <child link="Knee_Foot_bracket_R1"/>
  <axis xyz="1.0 -0.0 0.0"/>
</joint>
<transmission name="Revolute_60_tran">
  <type>transmission_interface/SimpleTransmission</type>
  <joint name="Revolute_60">
    <hardwareInterface>PositionJointInterface</hardwareInterface>
  </joint>
  <actuator name="Revolute_60_actr">
    <hardwareInterface>PositionJointInterface</hardwareInterface>
    <mechanicalReduction>1</mechanicalReduction>
  </actuator>
</transmission>

<joint name="Revolute_61" type="continuous">
  <origin xyz="-0.00575 0.0085 -0.0358" rpy="0 0 0"/>
  <parent link="Knee_servo_Pitch_L1"/>
  <child link="Knee_Foot_Bracket_L1"/>
  <axis xyz="-1.0 0.0 -0.0"/>
</joint>
<transmission name="Revolute_61_tran">
  <type>transmission_interface/SimpleTransmission</type>
  <joint name="Revolute_61">
    <hardwareInterface>PositionJointInterface</hardwareInterface>
  </joint>
  <actuator name="Revolute_61_actr">
    <hardwareInterface>PositionJointInterface</hardwareInterface>
    <mechanicalReduction>1</mechanicalReduction>
  </actuator>
</transmission>

<joint name="Revolute_64" type="continuous">
  <origin xyz="0.0415 -0.0005 -0.099998" rpy="0 0 0"/>
  <parent link="Knee_Foot_Bracket_L1"/>
  <child link="Foot_servo_pitch_L1"/>
  <axis xyz="1.0 -0.0 0.0"/>
</joint>
<transmission name="Revolute_64_tran">
  <type>transmission_interface/SimpleTransmission</type>
  <joint name="Revolute_64">
    <hardwareInterface>PositionJointInterface</hardwareInterface>
  </joint>
  <actuator name="Revolute_64_actr">
    <hardwareInterface>PositionJointInterface</hardwareInterface>
    <mechanicalReduction>1</mechanicalReduction>
  </actuator>
</transmission>

<joint name="Rigid_65" type="fixed">
  <origin xyz="0.045512 0.032925 -0.045099" rpy="0 0 0"/>
  <parent link="Foot_servo_pitch_L1"/>
  <child link="Horn_foot_L1"/>
</joint>

<joint name="Revolute_66" type="continuous">
  <origin xyz="-0.0415 -0.0005 -0.099999" rpy="0 0 0"/>
  <parent link="Knee_Foot_bracket_R1"/>
  <child link="Foot_servo_pitch_R1"/>
  <axis xyz="1.0 -0.0 -0.0"/>
</joint>
<transmission name="Revolute_66_tran">
  <type>transmission_interface/SimpleTransmission</type>
  <joint name="Revolute_66">
    <hardwareInterface>PositionJointInterface</hardwareInterface>
  </joint>
  <actuator name="Revolute_66_actr">
    <hardwareInterface>PositionJointInterface</hardwareInterface>
    <mechanicalReduction>1</mechanicalReduction>
  </actuator>
</transmission>

<joint name="Rigid_67" type="fixed">
  <origin xyz="-0.045687 0.077176 -0.045094" rpy="0 0 0"/>
  <parent link="Foot_servo_pitch_R1"/>
  <child link="horn_foot_R1"/>
</joint>

<joint name="Rigid_68" type="fixed">
  <origin xyz="-0.03575 -0.015 0.0295" rpy="0 0 0"/>
  <parent link="Foot_servo_pitch_L1"/>
  <child link="side_attach_foot_L1"/>
</joint>

<joint name="Rigid_69" type="fixed">
  <origin xyz="0.00575 -0.015 0.0295" rpy="0 0 0"/>
  <parent link="Foot_servo_pitch_R1"/>
  <child link="side_attach_foot_R1"/>
</joint>

<joint name="Rigid_70" type="fixed">
  <origin xyz="0.015 -0.0058 -0.0295" rpy="0 0 0"/>
  <parent link="side_attach_foot_L1"/>
  <child link="Washer_31"/>
</joint>

<joint name="Rigid_71" type="fixed">
  <origin xyz="0.015 -0.0058 -0.0295" rpy="0 0 0"/>
  <parent link="side_attach_foot_R1"/>
  <child link="Washer_41"/>
</joint>

<joint name="Rigid_72" type="fixed">
  <origin xyz="0.03575 0.0085 0.0358" rpy="0 0 0"/>
  <parent link="Foot_servo_pitch_R1"/>
  <child link="support_attach_foot_R1"/>
</joint>

<joint name="Rigid_73" type="fixed">
  <origin xyz="-0.03575 0.0085 0.0358" rpy="0 0 0"/>
  <parent link="Foot_servo_pitch_L1"/>
  <child link="support_attach_foot_L1"/>
</joint>

<joint name="Rigid_74" type="fixed">
  <origin xyz="-0.023498 0.01853 1.3e-05" rpy="0 0 0"/>
  <parent link="support_attach_foot_R1"/>
  <child link="foot_Servo_roll_R1"/>
</joint>

<joint name="Rigid_75" type="fixed">
  <origin xyz="0.006502 0.01853 -1.3e-05" rpy="0 0 0"/>
  <parent link="support_attach_foot_L1"/>
  <child link="foot_servo_roll_L1"/>
</joint>

<joint name="Revolute_76" type="continuous">
  <origin xyz="0.0085 -0.00575 -0.0358" rpy="0 0 0"/>
  <parent link="foot_Servo_roll_R1"/>
  <child link="foot_connect_R1"/>
  <axis xyz="-0.0 -1.0 -0.0"/>
</joint>
<transmission name="Revolute_76_tran">
  <type>transmission_interface/SimpleTransmission</type>
  <joint name="Revolute_76">
    <hardwareInterface>PositionJointInterface</hardwareInterface>
  </joint>
  <actuator name="Revolute_76_actr">
    <hardwareInterface>PositionJointInterface</hardwareInterface>
    <mechanicalReduction>1</mechanicalReduction>
  </actuator>
</transmission>

<joint name="Revolute_77" type="continuous">
  <origin xyz="0.0085 -0.00575 -0.0358" rpy="0 0 0"/>
  <parent link="foot_servo_roll_L1"/>
  <child link="foot_connect_L1"/>
  <axis xyz="-0.0 -1.0 -0.0"/>
</joint>
<transmission name="Revolute_77_tran">
  <type>transmission_interface/SimpleTransmission</type>
  <joint name="Revolute_77">
    <hardwareInterface>PositionJointInterface</hardwareInterface>
  </joint>
  <actuator name="Revolute_77_actr">
    <hardwareInterface>PositionJointInterface</hardwareInterface>
    <mechanicalReduction>1</mechanicalReduction>
  </actuator>
</transmission>

<joint name="Rigid_78" type="fixed">
  <origin xyz="-0.098626 0.010107 0.036187" rpy="0 0 0"/>
  <parent link="Washer_41"/>
  <child link="Bush_31"/>
</joint>

<joint name="Rigid_79" type="fixed">
  <origin xyz="-0.022626 0.010102 0.036012" rpy="0 0 0"/>
  <parent link="Washer_31"/>
  <child link="Bush_41"/>
</joint>

<joint name="Rigid_82" type="fixed">
  <origin xyz="0.022128 0.218498 -0.042626" rpy="0 0 0"/>
  <parent link="Bush_2_1"/>
  <child link="Washer_21"/>
</joint>

<joint name="Rigid_85" type="fixed">
  <origin xyz="-0.006 -0.0365 -0.034" rpy="0 0 0"/>
  <parent link="foot_connect_L1"/>
  <child link="Foot_L1"/>
</joint>

<joint name="Rigid_86" type="fixed">
  <origin xyz="-0.006 -0.0115 -0.034" rpy="0 0 0"/>
  <parent link="foot_connect_R1"/>
  <child link="Foot_R1"/>
</joint>

</robot>
